Performing Yearly calculation for 211001 to 221001
    Now on station 3510
Reading observational dataframe for PCPTOT.. 
Now on.. MM5_g2 for PCPTOT
Traceback (most recent call last):
  File "mk_weighted_ensemble.py", line 297, in <module>
    main(sys.argv)
  File "mk_weighted_ensemble.py", line 254, in main
    fcst, model_df_name = fcst_grab(station_df, savetype, stat_type, k, weight_type, filepath, delta, input_domain,  \
TypeError: fcst_grab() takes 18 positional arguments but 19 were given
Performing Yearly calculation for 211001 to 221001
    Now on station 3510
Reading observational dataframe for PCPTOT.. 
Traceback (most recent call last):
  File "mk_weighted_ensemble.py", line 297, in <module>
    main(sys.argv)
  File "mk_weighted_ensemble.py", line 192, in main
    obs_df = PCPT_obs_df_6(date_list_obs, delta, input_variable, station, start_date, end_date, all_stations)
  File "/nfs/neltharion/oper_users/verif/verif-post-process/weights/ensemble/funcs.py", line 434, in PCPT_obs_df_6
    obs_df_1 = obs_df_1.append(obs_df_1.iloc[60],ignore_index=True)
  File "/home/verif/.conda/envs/verification/lib/python3.8/site-packages/pandas/core/indexing.py", line 1768, in __getitem__
    return self._getitem_axis(maybe_callable, axis=axis)
  File "/home/verif/.conda/envs/verification/lib/python3.8/site-packages/pandas/core/indexing.py", line 2138, in _getitem_axis
    self._validate_integer(key, axis)
  File "/home/verif/.conda/envs/verification/lib/python3.8/site-packages/pandas/core/indexing.py", line 2063, in _validate_integer
    raise IndexError("single positional indexer is out-of-bounds")
IndexError: single positional indexer is out-of-bounds
Performing Yearly calculation for 211001 to 221001
    Now on station 3510
Reading observational dataframe for SFCTC.. 
Now on.. MM5_g2 for SFCTC
Traceback (most recent call last):
  File "mk_weighted_ensemble.py", line 297, in <module>
    main(sys.argv)
  File "mk_weighted_ensemble.py", line 254, in main
    fcst, model_df_name = fcst_grab(station_df, savetype, stat_type, k, weight_type, filepath, delta, input_domain,  \
TypeError: fcst_grab() takes 18 positional arguments but 19 were given
Performing Yearly calculation for 211001 to 221001
    Now on station 3510
Reading observational dataframe for SFCTC_KF.. 
Now on.. MM5_g2 for SFCTC_KF
Traceback (most recent call last):
  File "mk_weighted_ensemble.py", line 297, in <module>
    main(sys.argv)
  File "mk_weighted_ensemble.py", line 254, in main
    fcst, model_df_name = fcst_grab(station_df, savetype, stat_type, k, weight_type, filepath, delta, input_domain,  \
TypeError: fcst_grab() takes 18 positional arguments but 19 were given
Performing Yearly calculation for 211001 to 221001
    Now on station 3510
Reading observational dataframe for SFCWSPD.. 
Now on.. MM5_g2 for SFCWSPD
Traceback (most recent call last):
  File "mk_weighted_ensemble.py", line 297, in <module>
    main(sys.argv)
  File "mk_weighted_ensemble.py", line 254, in main
    fcst, model_df_name = fcst_grab(station_df, savetype, stat_type, k, weight_type, filepath, delta, input_domain,  \
TypeError: fcst_grab() takes 18 positional arguments but 19 were given
Performing Yearly calculation for 211001 to 221001
    Now on station 3510
Reading observational dataframe for SFCWSPD_KF.. 
Now on.. MM5_g2 for SFCWSPD_KF
Traceback (most recent call last):
  File "mk_weighted_ensemble.py", line 297, in <module>
    main(sys.argv)
  File "mk_weighted_ensemble.py", line 254, in main
    fcst, model_df_name = fcst_grab(station_df, savetype, stat_type, k, weight_type, filepath, delta, input_domain,  \
TypeError: fcst_grab() takes 18 positional arguments but 19 were given
Performing Yearly calculation for 211001 to 221001
    Now on station 3510
Reading observational dataframe for PCPTOT.. 
Now on.. MM5_g2 for PCPTOT
Traceback (most recent call last):
  File "mk_weighted_ensemble.py", line 297, in <module>
    main(sys.argv)
  File "mk_weighted_ensemble.py", line 254, in main
    fcst, model_df_name = fcst_grab(station_df, savetype, stat_type, k, weight_type, filepath, delta, input_domain,  \
TypeError: fcst_grab() takes 18 positional arguments but 19 were given
Performing Yearly calculation for 211001 to 221001
    Now on station 3510
Reading observational dataframe for PCPTOT.. 
Traceback (most recent call last):
  File "mk_weighted_ensemble.py", line 297, in <module>
    main(sys.argv)
  File "mk_weighted_ensemble.py", line 192, in main
    obs_df = PCPT_obs_df_6(date_list_obs, delta, input_variable, station, start_date, end_date, all_stations)
  File "/nfs/neltharion/oper_users/verif/verif-post-process/weights/ensemble/funcs.py", line 434, in PCPT_obs_df_6
    obs_df_1 = obs_df_1.append(obs_df_1.iloc[60],ignore_index=True)
  File "/home/verif/.conda/envs/verification/lib/python3.8/site-packages/pandas/core/indexing.py", line 1768, in __getitem__
    return self._getitem_axis(maybe_callable, axis=axis)
  File "/home/verif/.conda/envs/verification/lib/python3.8/site-packages/pandas/core/indexing.py", line 2138, in _getitem_axis
    self._validate_integer(key, axis)
  File "/home/verif/.conda/envs/verification/lib/python3.8/site-packages/pandas/core/indexing.py", line 2063, in _validate_integer
    raise IndexError("single positional indexer is out-of-bounds")
IndexError: single positional indexer is out-of-bounds
Performing Yearly calculation for 211001 to 221001
    Now on station 3510
Reading observational dataframe for SFCTC.. 
Now on.. MM5_g2 for SFCTC
Traceback (most recent call last):
  File "mk_weighted_ensemble.py", line 297, in <module>
    main(sys.argv)
  File "mk_weighted_ensemble.py", line 254, in main
    fcst, model_df_name = fcst_grab(station_df, savetype, stat_type, k, weight_type, filepath, delta, input_domain,  \
TypeError: fcst_grab() takes 18 positional arguments but 19 were given
Performing Yearly calculation for 211001 to 221001
    Now on station 3510
Reading observational dataframe for SFCTC_KF.. 
Now on.. MM5_g2 for SFCTC_KF
Traceback (most recent call last):
  File "mk_weighted_ensemble.py", line 297, in <module>
    main(sys.argv)
  File "mk_weighted_ensemble.py", line 254, in main
    fcst, model_df_name = fcst_grab(station_df, savetype, stat_type, k, weight_type, filepath, delta, input_domain,  \
TypeError: fcst_grab() takes 18 positional arguments but 19 were given
Performing Yearly calculation for 211001 to 221001
    Now on station 3510
Reading observational dataframe for SFCWSPD.. 
Now on.. MM5_g2 for SFCWSPD
Traceback (most recent call last):
  File "mk_weighted_ensemble.py", line 297, in <module>
    main(sys.argv)
  File "mk_weighted_ensemble.py", line 254, in main
    fcst, model_df_name = fcst_grab(station_df, savetype, stat_type, k, weight_type, filepath, delta, input_domain,  \
TypeError: fcst_grab() takes 18 positional arguments but 19 were given
Performing Yearly calculation for 211001 to 221001
    Now on station 3510
Reading observational dataframe for SFCWSPD_KF.. 
Now on.. MM5_g2 for SFCWSPD_KF
Traceback (most recent call last):
  File "mk_weighted_ensemble.py", line 297, in <module>
    main(sys.argv)
  File "mk_weighted_ensemble.py", line 254, in main
    fcst, model_df_name = fcst_grab(station_df, savetype, stat_type, k, weight_type, filepath, delta, input_domain,  \
TypeError: fcst_grab() takes 18 positional arguments but 19 were given
Performing Yearly calculation for 211001 to 221001
    Now on station 3510
Reading observational dataframe for PCPTOT.. 
Now on.. MM5_g2 for PCPTOT
Traceback (most recent call last):
  File "mk_weighted_ensemble.py", line 297, in <module>
    main(sys.argv)
  File "mk_weighted_ensemble.py", line 254, in main
    fcst, model_df_name = fcst_grab(station_df, savetype, stat_type, k, weight_type, filepath, delta, input_domain,  \
TypeError: fcst_grab() takes 18 positional arguments but 19 were given
Performing Yearly calculation for 211001 to 221001
    Now on station 3510
Reading observational dataframe for PCPTOT.. 
Traceback (most recent call last):
  File "mk_weighted_ensemble.py", line 297, in <module>
    main(sys.argv)
  File "mk_weighted_ensemble.py", line 192, in main
    obs_df = PCPT_obs_df_6(date_list_obs, delta, input_variable, station, start_date, end_date, all_stations)
  File "/nfs/neltharion/oper_users/verif/verif-post-process/weights/ensemble/funcs.py", line 434, in PCPT_obs_df_6
    obs_df_1 = obs_df_1.append(obs_df_1.iloc[60],ignore_index=True)
  File "/home/verif/.conda/envs/verification/lib/python3.8/site-packages/pandas/core/indexing.py", line 1768, in __getitem__
    return self._getitem_axis(maybe_callable, axis=axis)
  File "/home/verif/.conda/envs/verification/lib/python3.8/site-packages/pandas/core/indexing.py", line 2138, in _getitem_axis
    self._validate_integer(key, axis)
  File "/home/verif/.conda/envs/verification/lib/python3.8/site-packages/pandas/core/indexing.py", line 2063, in _validate_integer
    raise IndexError("single positional indexer is out-of-bounds")
IndexError: single positional indexer is out-of-bounds
Performing Yearly calculation for 211001 to 221001
    Now on station 3510
Reading observational dataframe for SFCTC.. 
Now on.. MM5_g2 for SFCTC
Traceback (most recent call last):
  File "mk_weighted_ensemble.py", line 297, in <module>
    main(sys.argv)
  File "mk_weighted_ensemble.py", line 254, in main
    fcst, model_df_name = fcst_grab(station_df, savetype, stat_type, k, weight_type, filepath, delta, input_domain,  \
TypeError: fcst_grab() takes 18 positional arguments but 19 were given
Performing Yearly calculation for 211001 to 221001
    Now on station 3510
Reading observational dataframe for SFCTC_KF.. 
Now on.. MM5_g2 for SFCTC_KF
Traceback (most recent call last):
  File "mk_weighted_ensemble.py", line 297, in <module>
    main(sys.argv)
  File "mk_weighted_ensemble.py", line 254, in main
    fcst, model_df_name = fcst_grab(station_df, savetype, stat_type, k, weight_type, filepath, delta, input_domain,  \
TypeError: fcst_grab() takes 18 positional arguments but 19 were given
Performing Yearly calculation for 211001 to 221001
    Now on station 3510
Reading observational dataframe for SFCWSPD.. 
Now on.. MM5_g2 for SFCWSPD
Traceback (most recent call last):
  File "mk_weighted_ensemble.py", line 297, in <module>
    main(sys.argv)
  File "mk_weighted_ensemble.py", line 254, in main
    fcst, model_df_name = fcst_grab(station_df, savetype, stat_type, k, weight_type, filepath, delta, input_domain,  \
TypeError: fcst_grab() takes 18 positional arguments but 19 were given
Performing Yearly calculation for 211001 to 221001
    Now on station 3510
Reading observational dataframe for SFCWSPD_KF.. 
Now on.. MM5_g2 for SFCWSPD_KF
Traceback (most recent call last):
  File "mk_weighted_ensemble.py", line 297, in <module>
    main(sys.argv)
  File "mk_weighted_ensemble.py", line 254, in main
    fcst, model_df_name = fcst_grab(station_df, savetype, stat_type, k, weight_type, filepath, delta, input_domain,  \
TypeError: fcst_grab() takes 18 positional arguments but 19 were given
Performing Yearly calculation for 211001 to 221001
    Now on station 3510
Reading observational dataframe for PCPTOT.. 
Now on.. MM5_g2 for PCPTOT
Traceback (most recent call last):
  File "mk_weighted_ensemble.py", line 297, in <module>
    main(sys.argv)
  File "mk_weighted_ensemble.py", line 254, in main
    fcst, model_df_name = fcst_grab(station_df, savetype, stat_type, k, weight_type, filepath, delta, input_domain,  \
TypeError: fcst_grab() takes 18 positional arguments but 19 were given
Performing Yearly calculation for 211001 to 221001
    Now on station 3510
Reading observational dataframe for PCPTOT.. 
Traceback (most recent call last):
  File "mk_weighted_ensemble.py", line 297, in <module>
    main(sys.argv)
  File "mk_weighted_ensemble.py", line 192, in main
    obs_df = PCPT_obs_df_6(date_list_obs, delta, input_variable, station, start_date, end_date, all_stations)
  File "/nfs/neltharion/oper_users/verif/verif-post-process/weights/ensemble/funcs.py", line 434, in PCPT_obs_df_6
    obs_df_1 = obs_df_1.append(obs_df_1.iloc[60],ignore_index=True)
  File "/home/verif/.conda/envs/verification/lib/python3.8/site-packages/pandas/core/indexing.py", line 1768, in __getitem__
    return self._getitem_axis(maybe_callable, axis=axis)
  File "/home/verif/.conda/envs/verification/lib/python3.8/site-packages/pandas/core/indexing.py", line 2138, in _getitem_axis
    self._validate_integer(key, axis)
  File "/home/verif/.conda/envs/verification/lib/python3.8/site-packages/pandas/core/indexing.py", line 2063, in _validate_integer
    raise IndexError("single positional indexer is out-of-bounds")
IndexError: single positional indexer is out-of-bounds
Performing Yearly calculation for 211001 to 221001
Traceback (most recent call last):
  File "mk_weighted_ensemble.py", line 116, in <module>
    raise Exception("Invalid input options. CAT_ can only be used with precip and wind variables NOT temp.")
Exception: Invalid input options. CAT_ can only be used with precip and wind variables NOT temp.
Performing Yearly calculation for 211001 to 221001
Traceback (most recent call last):
  File "mk_weighted_ensemble.py", line 116, in <module>
    raise Exception("Invalid input options. CAT_ can only be used with precip and wind variables NOT temp.")
Exception: Invalid input options. CAT_ can only be used with precip and wind variables NOT temp.
Performing Yearly calculation for 211001 to 221001
    Now on station 3510
Reading observational dataframe for SFCWSPD.. 
Now on.. MM5_g2 for SFCWSPD
Traceback (most recent call last):
  File "mk_weighted_ensemble.py", line 297, in <module>
    main(sys.argv)
  File "mk_weighted_ensemble.py", line 254, in main
    fcst, model_df_name = fcst_grab(station_df, savetype, stat_type, k, weight_type, filepath, delta, input_domain,  \
TypeError: fcst_grab() takes 18 positional arguments but 19 were given
Performing Yearly calculation for 211001 to 221001
    Now on station 3510
Reading observational dataframe for SFCWSPD_KF.. 
Now on.. MM5_g2 for SFCWSPD_KF
Traceback (most recent call last):
  File "mk_weighted_ensemble.py", line 297, in <module>
    main(sys.argv)
  File "mk_weighted_ensemble.py", line 254, in main
    fcst, model_df_name = fcst_grab(station_df, savetype, stat_type, k, weight_type, filepath, delta, input_domain,  \
TypeError: fcst_grab() takes 18 positional arguments but 19 were given
Performing Yearly calculation for 211001 to 221001
    Now on station 3510
Reading observational dataframe for PCPTOT.. 
Now on.. MM5_g2 for PCPTOT
Traceback (most recent call last):
  File "mk_weighted_ensemble.py", line 297, in <module>
    main(sys.argv)
  File "mk_weighted_ensemble.py", line 254, in main
    fcst, model_df_name = fcst_grab(station_df, savetype, stat_type, k, weight_type, filepath, delta, input_domain,  \
TypeError: fcst_grab() takes 18 positional arguments but 19 were given
Performing Yearly calculation for 211001 to 221001
    Now on station 3510
Reading observational dataframe for PCPTOT.. 
Traceback (most recent call last):
  File "mk_weighted_ensemble.py", line 297, in <module>
    main(sys.argv)
  File "mk_weighted_ensemble.py", line 192, in main
    obs_df = PCPT_obs_df_6(date_list_obs, delta, input_variable, station, start_date, end_date, all_stations)
  File "/nfs/neltharion/oper_users/verif/verif-post-process/weights/ensemble/funcs.py", line 434, in PCPT_obs_df_6
    obs_df_1 = obs_df_1.append(obs_df_1.iloc[60],ignore_index=True)
  File "/home/verif/.conda/envs/verification/lib/python3.8/site-packages/pandas/core/indexing.py", line 1768, in __getitem__
    return self._getitem_axis(maybe_callable, axis=axis)
  File "/home/verif/.conda/envs/verification/lib/python3.8/site-packages/pandas/core/indexing.py", line 2138, in _getitem_axis
    self._validate_integer(key, axis)
  File "/home/verif/.conda/envs/verification/lib/python3.8/site-packages/pandas/core/indexing.py", line 2063, in _validate_integer
    raise IndexError("single positional indexer is out-of-bounds")
IndexError: single positional indexer is out-of-bounds
Performing Yearly calculation for 211001 to 221001
Traceback (most recent call last):
  File "mk_weighted_ensemble.py", line 116, in <module>
    raise Exception("Invalid input options. CAT_ can only be used with precip and wind variables NOT temp.")
Exception: Invalid input options. CAT_ can only be used with precip and wind variables NOT temp.
Performing Yearly calculation for 211001 to 221001
Traceback (most recent call last):
  File "mk_weighted_ensemble.py", line 116, in <module>
    raise Exception("Invalid input options. CAT_ can only be used with precip and wind variables NOT temp.")
Exception: Invalid input options. CAT_ can only be used with precip and wind variables NOT temp.
Performing Yearly calculation for 211001 to 221001
    Now on station 3510
Reading observational dataframe for SFCWSPD.. 
Now on.. MM5_g2 for SFCWSPD
Traceback (most recent call last):
  File "mk_weighted_ensemble.py", line 297, in <module>
    main(sys.argv)
  File "mk_weighted_ensemble.py", line 254, in main
    fcst, model_df_name = fcst_grab(station_df, savetype, stat_type, k, weight_type, filepath, delta, input_domain,  \
TypeError: fcst_grab() takes 18 positional arguments but 19 were given
Performing Yearly calculation for 211001 to 221001
    Now on station 3510
Reading observational dataframe for SFCWSPD_KF.. 
Now on.. MM5_g2 for SFCWSPD_KF
Traceback (most recent call last):
  File "mk_weighted_ensemble.py", line 297, in <module>
    main(sys.argv)
  File "mk_weighted_ensemble.py", line 254, in main
    fcst, model_df_name = fcst_grab(station_df, savetype, stat_type, k, weight_type, filepath, delta, input_domain,  \
TypeError: fcst_grab() takes 18 positional arguments but 19 were given
Performing Yearly calculation for 211001 to 221001
    Now on station 3510
Reading observational dataframe for PCPTOT.. 
Now on.. MM5_g2 for PCPTOT
Traceback (most recent call last):
  File "mk_weighted_ensemble.py", line 297, in <module>
    main(sys.argv)
  File "mk_weighted_ensemble.py", line 254, in main
    fcst, model_df_name = fcst_grab(station_df, savetype, stat_type, k, weight_type, filepath, delta, input_domain,  \
TypeError: fcst_grab() takes 18 positional arguments but 19 were given
Performing Yearly calculation for 211001 to 221001
    Now on station 3510
Reading observational dataframe for PCPTOT.. 
Traceback (most recent call last):
  File "mk_weighted_ensemble.py", line 297, in <module>
    main(sys.argv)
  File "mk_weighted_ensemble.py", line 192, in main
    obs_df = PCPT_obs_df_6(date_list_obs, delta, input_variable, station, start_date, end_date, all_stations)
  File "/nfs/neltharion/oper_users/verif/verif-post-process/weights/ensemble/funcs.py", line 434, in PCPT_obs_df_6
    obs_df_1 = obs_df_1.append(obs_df_1.iloc[60],ignore_index=True)
  File "/home/verif/.conda/envs/verification/lib/python3.8/site-packages/pandas/core/indexing.py", line 1768, in __getitem__
    return self._getitem_axis(maybe_callable, axis=axis)
  File "/home/verif/.conda/envs/verification/lib/python3.8/site-packages/pandas/core/indexing.py", line 2138, in _getitem_axis
    self._validate_integer(key, axis)
  File "/home/verif/.conda/envs/verification/lib/python3.8/site-packages/pandas/core/indexing.py", line 2063, in _validate_integer
    raise IndexError("single positional indexer is out-of-bounds")
IndexError: single positional indexer is out-of-bounds
Performing Yearly calculation for 211001 to 221001
Traceback (most recent call last):
  File "mk_weighted_ensemble.py", line 116, in <module>
    raise Exception("Invalid input options. CAT_ can only be used with precip and wind variables NOT temp.")
Exception: Invalid input options. CAT_ can only be used with precip and wind variables NOT temp.
Performing Yearly calculation for 211001 to 221001
Traceback (most recent call last):
  File "mk_weighted_ensemble.py", line 116, in <module>
    raise Exception("Invalid input options. CAT_ can only be used with precip and wind variables NOT temp.")
Exception: Invalid input options. CAT_ can only be used with precip and wind variables NOT temp.
Performing Yearly calculation for 211001 to 221001
    Now on station 3510
Reading observational dataframe for SFCWSPD.. 
Now on.. MM5_g2 for SFCWSPD
Traceback (most recent call last):
  File "mk_weighted_ensemble.py", line 297, in <module>
    main(sys.argv)
  File "mk_weighted_ensemble.py", line 254, in main
    fcst, model_df_name = fcst_grab(station_df, savetype, stat_type, k, weight_type, filepath, delta, input_domain,  \
TypeError: fcst_grab() takes 18 positional arguments but 19 were given
Performing Yearly calculation for 211001 to 221001
    Now on station 3510
Reading observational dataframe for SFCWSPD_KF.. 
Now on.. MM5_g2 for SFCWSPD_KF
Traceback (most recent call last):
  File "mk_weighted_ensemble.py", line 297, in <module>
    main(sys.argv)
  File "mk_weighted_ensemble.py", line 254, in main
    fcst, model_df_name = fcst_grab(station_df, savetype, stat_type, k, weight_type, filepath, delta, input_domain,  \
TypeError: fcst_grab() takes 18 positional arguments but 19 were given
Performing Yearly calculation for 211001 to 221001
    Now on station 3510
Reading observational dataframe for PCPTOT.. 
Now on.. MM5_g2 for PCPTOT
Traceback (most recent call last):
  File "mk_weighted_ensemble.py", line 297, in <module>
    main(sys.argv)
  File "mk_weighted_ensemble.py", line 254, in main
    fcst, model_df_name = fcst_grab(station_df, savetype, stat_type, k, weight_type, filepath, delta, input_domain,  \
TypeError: fcst_grab() takes 18 positional arguments but 19 were given
Performing Yearly calculation for 211001 to 221001
    Now on station 3510
Reading observational dataframe for PCPTOT.. 
Traceback (most recent call last):
  File "mk_weighted_ensemble.py", line 297, in <module>
    main(sys.argv)
  File "mk_weighted_ensemble.py", line 192, in main
    obs_df = PCPT_obs_df_6(date_list_obs, delta, input_variable, station, start_date, end_date, all_stations)
  File "/nfs/neltharion/oper_users/verif/verif-post-process/weights/ensemble/funcs.py", line 434, in PCPT_obs_df_6
    obs_df_1 = obs_df_1.append(obs_df_1.iloc[60],ignore_index=True)
  File "/home/verif/.conda/envs/verification/lib/python3.8/site-packages/pandas/core/indexing.py", line 1768, in __getitem__
    return self._getitem_axis(maybe_callable, axis=axis)
  File "/home/verif/.conda/envs/verification/lib/python3.8/site-packages/pandas/core/indexing.py", line 2138, in _getitem_axis
    self._validate_integer(key, axis)
  File "/home/verif/.conda/envs/verification/lib/python3.8/site-packages/pandas/core/indexing.py", line 2063, in _validate_integer
    raise IndexError("single positional indexer is out-of-bounds")
IndexError: single positional indexer is out-of-bounds
Performing Yearly calculation for 211001 to 221001
Traceback (most recent call last):
  File "mk_weighted_ensemble.py", line 116, in <module>
    raise Exception("Invalid input options. CAT_ can only be used with precip and wind variables NOT temp.")
Exception: Invalid input options. CAT_ can only be used with precip and wind variables NOT temp.
Performing Yearly calculation for 211001 to 221001
Traceback (most recent call last):
  File "mk_weighted_ensemble.py", line 116, in <module>
    raise Exception("Invalid input options. CAT_ can only be used with precip and wind variables NOT temp.")
Exception: Invalid input options. CAT_ can only be used with precip and wind variables NOT temp.
Performing Yearly calculation for 211001 to 221001
    Now on station 3510
Reading observational dataframe for SFCWSPD.. 
Now on.. MM5_g2 for SFCWSPD
Traceback (most recent call last):
  File "mk_weighted_ensemble.py", line 297, in <module>
    main(sys.argv)
  File "mk_weighted_ensemble.py", line 254, in main
    fcst, model_df_name = fcst_grab(station_df, savetype, stat_type, k, weight_type, filepath, delta, input_domain,  \
TypeError: fcst_grab() takes 18 positional arguments but 19 were given
Performing Yearly calculation for 211001 to 221001
    Now on station 3510
Reading observational dataframe for SFCWSPD_KF.. 
Now on.. MM5_g2 for SFCWSPD_KF
Traceback (most recent call last):
  File "mk_weighted_ensemble.py", line 297, in <module>
    main(sys.argv)
  File "mk_weighted_ensemble.py", line 254, in main
    fcst, model_df_name = fcst_grab(station_df, savetype, stat_type, k, weight_type, filepath, delta, input_domain,  \
TypeError: fcst_grab() takes 18 positional arguments but 19 were given
Performing Yearly calculation for 211001 to 221001
    Now on station 3510
Reading observational dataframe for PCPTOT.. 
Now on.. MM5_g2 for PCPTOT
Traceback (most recent call last):
  File "mk_weighted_ensemble.py", line 297, in <module>
    main(sys.argv)
  File "mk_weighted_ensemble.py", line 254, in main
    fcst, model_df_name = fcst_grab(station_df, savetype, stat_type, k, weight_type, filepath, delta, input_domain,  \
TypeError: fcst_grab() takes 18 positional arguments but 19 were given
Performing Yearly calculation for 211001 to 221001
    Now on station 3510
Reading observational dataframe for PCPTOT.. 
Traceback (most recent call last):
  File "mk_weighted_ensemble.py", line 297, in <module>
    main(sys.argv)
  File "mk_weighted_ensemble.py", line 192, in main
    obs_df = PCPT_obs_df_6(date_list_obs, delta, input_variable, station, start_date, end_date, all_stations)
  File "/nfs/neltharion/oper_users/verif/verif-post-process/weights/ensemble/funcs.py", line 434, in PCPT_obs_df_6
    obs_df_1 = obs_df_1.append(obs_df_1.iloc[60],ignore_index=True)
  File "/home/verif/.conda/envs/verification/lib/python3.8/site-packages/pandas/core/indexing.py", line 1768, in __getitem__
    return self._getitem_axis(maybe_callable, axis=axis)
  File "/home/verif/.conda/envs/verification/lib/python3.8/site-packages/pandas/core/indexing.py", line 2138, in _getitem_axis
    self._validate_integer(key, axis)
  File "/home/verif/.conda/envs/verification/lib/python3.8/site-packages/pandas/core/indexing.py", line 2063, in _validate_integer
    raise IndexError("single positional indexer is out-of-bounds")
IndexError: single positional indexer is out-of-bounds
Performing Yearly calculation for 211001 to 221001
Traceback (most recent call last):
  File "mk_weighted_ensemble.py", line 116, in <module>
    raise Exception("Invalid input options. CAT_ can only be used with precip and wind variables NOT temp.")
Exception: Invalid input options. CAT_ can only be used with precip and wind variables NOT temp.
Performing Yearly calculation for 211001 to 221001
Traceback (most recent call last):
  File "mk_weighted_ensemble.py", line 116, in <module>
    raise Exception("Invalid input options. CAT_ can only be used with precip and wind variables NOT temp.")
Exception: Invalid input options. CAT_ can only be used with precip and wind variables NOT temp.
Performing Yearly calculation for 211001 to 221001
    Now on station 3510
Reading observational dataframe for SFCWSPD.. 
Now on.. MM5_g2 for SFCWSPD
Traceback (most recent call last):
  File "mk_weighted_ensemble.py", line 297, in <module>
    main(sys.argv)
  File "mk_weighted_ensemble.py", line 254, in main
    fcst, model_df_name = fcst_grab(station_df, savetype, stat_type, k, weight_type, filepath, delta, input_domain,  \
TypeError: fcst_grab() takes 18 positional arguments but 19 were given
Performing Yearly calculation for 211001 to 221001
    Now on station 3510
Reading observational dataframe for SFCWSPD_KF.. 
Now on.. MM5_g2 for SFCWSPD_KF
Traceback (most recent call last):
  File "mk_weighted_ensemble.py", line 297, in <module>
    main(sys.argv)
  File "mk_weighted_ensemble.py", line 254, in main
    fcst, model_df_name = fcst_grab(station_df, savetype, stat_type, k, weight_type, filepath, delta, input_domain,  \
TypeError: fcst_grab() takes 18 positional arguments but 19 were given
Performing Yearly calculation for 211001 to 221001
    Now on station 3510
Reading observational dataframe for PCPTOT.. 
Now on.. MM5_g2 for PCPTOT
Traceback (most recent call last):
  File "mk_weighted_ensemble.py", line 297, in <module>
    main(sys.argv)
  File "mk_weighted_ensemble.py", line 254, in main
    fcst, model_df_name = fcst_grab(station_df, savetype, stat_type, k, weight_type, filepath, delta, input_domain,  \
TypeError: fcst_grab() takes 18 positional arguments but 19 were given
Performing Yearly calculation for 211001 to 221001
    Now on station 3510
Reading observational dataframe for PCPTOT.. 
Traceback (most recent call last):
  File "mk_weighted_ensemble.py", line 297, in <module>
    main(sys.argv)
  File "mk_weighted_ensemble.py", line 192, in main
    obs_df = PCPT_obs_df_6(date_list_obs, delta, input_variable, station, start_date, end_date, all_stations)
  File "/nfs/neltharion/oper_users/verif/verif-post-process/weights/ensemble/funcs.py", line 434, in PCPT_obs_df_6
    obs_df_1 = obs_df_1.append(obs_df_1.iloc[60],ignore_index=True)
  File "/home/verif/.conda/envs/verification/lib/python3.8/site-packages/pandas/core/indexing.py", line 1768, in __getitem__
    return self._getitem_axis(maybe_callable, axis=axis)
  File "/home/verif/.conda/envs/verification/lib/python3.8/site-packages/pandas/core/indexing.py", line 2138, in _getitem_axis
    self._validate_integer(key, axis)
  File "/home/verif/.conda/envs/verification/lib/python3.8/site-packages/pandas/core/indexing.py", line 2063, in _validate_integer
    raise IndexError("single positional indexer is out-of-bounds")
IndexError: single positional indexer is out-of-bounds
Performing Yearly calculation for 211001 to 221001
Traceback (most recent call last):
  File "mk_weighted_ensemble.py", line 116, in <module>
    raise Exception("Invalid input options. CAT_ can only be used with precip and wind variables NOT temp.")
Exception: Invalid input options. CAT_ can only be used with precip and wind variables NOT temp.
Performing Yearly calculation for 211001 to 221001
Traceback (most recent call last):
  File "mk_weighted_ensemble.py", line 116, in <module>
    raise Exception("Invalid input options. CAT_ can only be used with precip and wind variables NOT temp.")
Exception: Invalid input options. CAT_ can only be used with precip and wind variables NOT temp.
Performing Yearly calculation for 211001 to 221001
    Now on station 3510
Reading observational dataframe for SFCWSPD.. 
Now on.. MM5_g2 for SFCWSPD
Traceback (most recent call last):
  File "mk_weighted_ensemble.py", line 297, in <module>
    main(sys.argv)
  File "mk_weighted_ensemble.py", line 254, in main
    fcst, model_df_name = fcst_grab(station_df, savetype, stat_type, k, weight_type, filepath, delta, input_domain,  \
TypeError: fcst_grab() takes 18 positional arguments but 19 were given
Performing Yearly calculation for 211001 to 221001
    Now on station 3510
Reading observational dataframe for SFCWSPD_KF.. 
Now on.. MM5_g2 for SFCWSPD_KF
Traceback (most recent call last):
  File "mk_weighted_ensemble.py", line 297, in <module>
    main(sys.argv)
  File "mk_weighted_ensemble.py", line 254, in main
    fcst, model_df_name = fcst_grab(station_df, savetype, stat_type, k, weight_type, filepath, delta, input_domain,  \
TypeError: fcst_grab() takes 18 positional arguments but 19 were given
